<?xml version="1.0" ?>
<!-- =================================================================================== -->
<!-- |    This document was autogenerated by xacro from src\fonbot_package\description\robot.urdf.xacro | -->
<!-- |    EDITING THIS FILE BY HAND IS NOT RECOMMENDED                                 | -->
<!-- =================================================================================== -->
<robot name="robot">
  <!-- Specify some standard inertial calculations https://en.wikipedia.org/wiki/List_of_moments_of_inertia -->
  <!-- These make use of xacro's mathematical functionality -->
  <material name="white">
    <color rgba="1 1 1 1"/>
  </material>
  <material name="orange">
    <color rgba="1 0.3 0.1 1"/>
  </material>
  <material name="blue">
    <color rgba="0.2 0.2 1 1"/>
  </material>
  <material name="black">
    <color rgba="0 0 0 1"/>
  </material>
  <!-- BASE -->
  <link name="base_link">
    </link>
  <!-- CHASSIS -->
  <joint name="chassis_joint" type="fixed">
    <parent link="base_link"/>
    <child link="chassis"/>
    <origin rpy="0 0 1.5707963267948966" xyz="0 0 0"/>
  </joint>
  <link name="chassis">
    <visual>
      <origin xyz="0 0.02 0.095"/>
      <geometry>
        <mesh filename="package://fonbot_package/models/chassis2.dae" scale="0.4 0.2 0.2"/>
      </geometry>
      <material name="white"/>
    </visual>
    <collision>
      <origin xyz="0 0.02 0.095"/>
      <geometry>
        <mesh filename="package://fonbot_package/models/chassis2.dae" scale="0.4 0.2 0.2"/>
      </geometry>
    </collision>
    <inertial>
      <origin rpy="0 0 0" xyz="0 0.02 0.095"/>
      <mass value="0.5"/>
      <inertia ixx="0.008333333333333335" ixy="0.0" ixz="0.0" iyy="0.008333333333333335" iyz="0.0" izz="0.013333333333333336"/>
    </inertial>
  </link>
  <!-- LEFT TRACK -->
  <joint name="left_track_joint" type="fixed">
    <parent link="chassis"/>
    <child link="left_track"/>
    <origin rpy="0 0 0" xyz="0.175 0 0.075"/>
    <axis xyz="-1 0 0"/>
  </joint>
  <link name="left_track">
    <visual>
      <geometry>
        <mesh filename="package://fonbot_package/models/tank-track-asym.dae" scale="0.2 0.2 0.2"/>
      </geometry>
      <material name="blue"/>
    </visual>
    <collision>
      <geometry>
        <mesh filename="package://fonbot_package/models/tank-track-asym.dae" scale="0.2 0.2 0.2"/>
      </geometry>
    </collision>
    <inertial>
      <origin rpy="0 0 0" xyz="0 0 0"/>
      <mass value="0.1"/>
      <inertia ixx="0.0015208333333333335" ixy="0.0" ixz="0.0" iyy="0.0002708333333333333" iyz="0.0" izz="0.001416666666666667"/>
    </inertial>
  </link>
  <!-- LEFT TRACK WHEELS -->
  <joint name="left_track_large_wheel_joint" type="continuous">
    <parent link="left_track"/>
    <child link="large_wheel_left"/>
    <origin xyz="0 0.095 0.03"/>
    <axis xyz="-1 0 0"/>
  </joint>
  <link name="large_wheel_left">
    <visual>
      <geometry>
        <mesh filename="package://fonbot_package/models/tank-wheel.dae" scale="0.32 0.32 0.32"/>
      </geometry>
    </visual>
    <collision>
      <geometry>
        <mesh filename="package://fonbot_package/models/tank-wheel.dae" scale="0.32 0.32 0.32"/>
      </geometry>
    </collision>
    <inertial>
      <origin rpy="0 1.5707963267948966 0" xyz="0 0 0"/>
      <mass value="0.1"/>
      <inertia ixx="0.0002708333333333334" ixy="0.0" ixz="0.0" iyy="0.0002708333333333334" iyz="0.0" izz="0.0005000000000000001"/>
    </inertial>
  </link>
  <joint name="left_track_small_wheel_joint" type="continuous">
    <parent link="left_track"/>
    <child link="small_wheel_left"/>
    <origin xyz="0 -0.13 0"/>
    <axis xyz="-1 0 0"/>
  </joint>
  <link name="small_wheel_left">
    <visual>
      <geometry>
        <mesh filename="package://fonbot_package/models/tank-wheel.dae" scale="0.2 0.2 0.2"/>
      </geometry>
    </visual>
    <collision>
      <geometry>
        <mesh filename="package://fonbot_package/models/tank-wheel.dae" scale="0.2 0.2 0.2"/>
      </geometry>
    </collision>
    <inertial>
      <origin rpy="0 1.5707963267948966 0" xyz="0 0 0"/>
      <mass value="0.05"/>
      <inertia ixx="4.166666666666667e-05" ixy="0.0" ixz="0.0" iyy="4.166666666666667e-05" iyz="0.0" izz="6.250000000000001e-05"/>
    </inertial>
  </link>
  <!-- RIGHT TRACK -->
  <joint name="right_track_joint" type="fixed">
    <parent link="chassis"/>
    <child link="right_track"/>
    <origin rpy="0 0 0" xyz="-0.175 0 0.075"/>
    <axis xyz="0 0 -1"/>
  </joint>
  <link name="right_track">
    <visual>
      <geometry>
        <mesh filename="package://fonbot_package/models/tank-track-asym.dae" scale="0.2 0.2 0.2"/>
      </geometry>
    </visual>
    <collision>
      <geometry>
        <mesh filename="package://fonbot_package/models/tank-track-asym.dae" scale="0.2 0.2 0.2"/>
      </geometry>
    </collision>
    <inertial>
      <origin rpy="0 0 0" xyz="0 0 0"/>
      <mass value="0.1"/>
      <inertia ixx="0.0015208333333333335" ixy="0.0" ixz="0.0" iyy="0.0002708333333333333" iyz="0.0" izz="0.001416666666666667"/>
    </inertial>
  </link>
  <!-- RIGHT TRACK WHEELS -->
  <joint name="right_track_large_wheel_joint" type="continuous">
    <parent link="right_track"/>
    <child link="large_wheel_right"/>
    <origin rpy="0 0 3.141592653589793" xyz="0 0.095 0.03"/>
    <axis xyz="1 0 0"/>
  </joint>
  <link name="large_wheel_right">
    <visual>
      <geometry>
        <mesh filename="package://fonbot_package/models/tank-wheel.dae" scale="0.32 0.32 0.32"/>
      </geometry>
    </visual>
    <collision>
      <geometry>
        <mesh filename="package://fonbot_package/models/tank-wheel.dae" scale="0.32 0.32 0.32"/>
      </geometry>
    </collision>
    <inertial>
      <origin rpy="0 1.5707963267948966 0" xyz="0 0 0"/>
      <mass value="0.1"/>
      <inertia ixx="0.0002708333333333334" ixy="0.0" ixz="0.0" iyy="0.0002708333333333334" iyz="0.0" izz="0.0005000000000000001"/>
    </inertial>
  </link>
  <joint name="right_track_small_wheel_joint" type="continuous">
    <parent link="right_track"/>
    <child link="small_wheel_right"/>
    <origin rpy="0 0 3.141592653589793" xyz="0 -0.13 0"/>
    <axis xyz="1 0 0"/>
  </joint>
  <link name="small_wheel_right">
    <visual>
      <geometry>
        <mesh filename="package://fonbot_package/models/tank-wheel.dae" scale="0.2 0.2 0.2"/>
      </geometry>
    </visual>
    <collision>
      <geometry>
        <mesh filename="package://fonbot_package/models/tank-wheel.dae" scale="0.2 0.2 0.2"/>
      </geometry>
    </collision>
    <inertial>
      <origin rpy="0 1.5707963267948966 0" xyz="0 0 0"/>
      <mass value="0.1"/>
      <inertia ixx="8.333333333333334e-05" ixy="0.0" ixz="0.0" iyy="8.333333333333334e-05" iyz="0.0" izz="0.00012500000000000003"/>
    </inertial>
  </link>
  <!-- HEAD ARM -->
  <joint name="chassis_connector_joint" type="fixed">
    <parent link="chassis"/>
    <child link="chassis_connector"/>
    <origin xyz="0 0.125 0.225"/>
  </joint>
  <link name="chassis_connector">
    <visual>
      <geometry>
        <cylinder length="0.05" radius="0.01"/>
      </geometry>
      <material name="black"/>
    </visual>
    <collision>
      <geometry>
        <cylinder length="0.05" radius="0.01"/>
      </geometry>
    </collision>
    <inertial>
      <origin rpy="0 0 0" xyz="0 0 0"/>
      <mass value="0.01"/>
      <inertia ixx="2.3333333333333336e-06" ixy="0.0" ixz="0.0" iyy="2.3333333333333336e-06" iyz="0.0" izz="5.000000000000001e-07"/>
    </inertial>
  </link>
  <joint name="head_rotation_point_joint" type="fixed">
    <parent link="chassis_connector"/>
    <child link="head_rotation_point"/>
    <origin rpy="0.0 0.0 0.0" xyz="0 0 0.025"/>
  </joint>
  <link name="head_rotation_point">
    <visual>
      <geometry>
        <sphere radius="0.015"/>
      </geometry>
    </visual>
    <collision>
      <geometry>
        <sphere radius="0.015"/>
      </geometry>
    </collision>
    <inertial>
      <origin rpy="0 0 0" xyz="0 0 0"/>
      <mass value="0.01"/>
      <inertia ixx="9e-07" ixy="0.0" ixz="0.0" iyy="9e-07" iyz="0.0" izz="9e-07"/>
    </inertial>
  </link>
  <joint name="head_connector_joint" type="revolute">
    <parent link="head_rotation_point"/>
    <child link="head_connector"/>
    <origin xyz="0 0 0.0075"/>
    <limit effort="1000.0" lower="0.0" upper="1.7951958020513104" velocity="0.5"/>
    <axis xyz="-1 0 0"/>
  </joint>
  <link name="head_connector">
    <visual>
      <origin xyz="0 0 0.025"/>
      <geometry>
        <cylinder length="0.05" radius="0.01"/>
      </geometry>
      <material name="black"/>
    </visual>
    <collision>
      <origin xyz="0 0 0.025"/>
      <geometry>
        <cylinder length="0.05" radius="0.01"/>
      </geometry>
    </collision>
    <inertial>
      <origin rpy="0 0 0" xyz="0 0 0"/>
      <mass value="0.01"/>
      <inertia ixx="2.3333333333333336e-06" ixy="0.0" ixz="0.0" iyy="2.3333333333333336e-06" iyz="0.0" izz="5.000000000000001e-07"/>
    </inertial>
  </link>
  <!-- HEAD -->
  <joint name="head_joint" type="fixed">
    <parent link="head_connector"/>
    <child link="head"/>
    <origin rpy="1.5707963267948966 0 0" xyz="0 0 0.05"/>
  </joint>
  <link name="head">
    <visual>
      <origin xyz="0 0.05 0"/>
      <geometry>
        <mesh filename="package://fonbot_package/models/head.dae" scale="0.2 0.2 0.2"/>
      </geometry>
    </visual>
    <collision>
      <origin xyz="0 0.05 0"/>
      <geometry>
        <mesh filename="package://fonbot_package/models/head.dae" scale="0.2 0.2 0.2"/>
      </geometry>
    </collision>
    <inertial>
      <origin rpy="0 0 0" xyz="0 0.05 0"/>
      <mass value="0.01"/>
      <inertia ixx="3.8666666666666674e-05" ixy="0.0" ixz="0.0" iyy="6.666666666666667e-05" iyz="0.0" izz="3.8666666666666674e-05"/>
    </inertial>
  </link>
  <!-- Specify some standard inertial calculations https://en.wikipedia.org/wiki/List_of_moments_of_inertia -->
  <!-- These make use of xacro's mathematical functionality -->
  <joint name="ultrasonic_front_joint" type="fixed">
    <parent link="chassis"/>
    <child link="ultrasonic_front"/>
    <origin xyz="0 0.205 0.125"/>
  </joint>
  <link name="ultrasonic_front">
    <visual>
      <origin rpy="-1.5707963267948966 1.5707963267948966 1.5707963267948966" xyz="-0.01 -0.02 -0.07"/>
      <geometry>
        <mesh filename="package://fonbot_package/models/ultrasonic.dae" scale="0.3 0.3 0.3"/>
      </geometry>
    </visual>
    <collision>
      <origin rpy="-1.5707963267948966 1.5707963267948966 1.5707963267948966" xyz="-0.01 -0.02 -0.07"/>
      <geometry>
        <mesh filename="package://fonbot_package/models/ultrasonic.dae" scale="0.3 0.3 0.3"/>
      </geometry>
    </collision>
    <!-- <xacro:inertial_box mass="0.05" x="0.2" y="0.2" z="0.2">
            <origin xyz="0 0 0" rpy="0 0 0" />
        </xacro:inertial_box> -->
  </link>
  <!-- Specify some standard inertial calculations https://en.wikipedia.org/wiki/List_of_moments_of_inertia -->
  <!-- These make use of xacro's mathematical functionality -->
  <joint name="ultrasonic_bottom_front_joint" type="fixed">
    <parent link="chassis"/>
    <child link="ultrasonic_bottom_front"/>
    <origin xyz="0 0.205 0.125"/>
  </joint>
  <link name="ultrasonic_bottom_front">
    <visual>
      <origin rpy="-1.5707963267948966 2.8559933214452666 1.5707963267948966" xyz="-0.01 -0.11 -0.098"/>
      <geometry>
        <mesh filename="package://fonbot_package/models/ultrasonic.dae" scale="0.3 0.3 0.3"/>
      </geometry>
    </visual>
    <collision>
      <origin rpy="-1.5707963267948966 2.8559933214452666 1.5707963267948966" xyz="-0.01 -0.11 -0.1"/>
      <geometry>
        <mesh filename="package://fonbot_package/models/ultrasonic.dae" scale="0.3 0.3 0.3"/>
      </geometry>
    </collision>
    <!-- <xacro:inertial_box mass="0.05" x="0.2" y="0.2" z="0.2">
            <origin xyz="0 0 0" rpy="0 0 0" />
        </xacro:inertial_box> -->
  </link>
  <!-- Specify some standard inertial calculations https://en.wikipedia.org/wiki/List_of_moments_of_inertia -->
  <!-- These make use of xacro's mathematical functionality -->
  <joint name="ultrasonic_back_joint" type="fixed">
    <parent link="chassis"/>
    <child link="ultrasonic_back"/>
    <origin xyz="0 0.205 0.125"/>
  </joint>
  <link name="ultrasonic_back">
    <visual>
      <origin rpy="1.5707963267948966 1.832595714594046 1.5707963267948966" xyz="-0.01 -0.4 -0.077"/>
      <geometry>
        <mesh filename="package://fonbot_package/models/ultrasonic.dae" scale="0.3 0.3 0.3"/>
      </geometry>
    </visual>
    <collision>
      <origin rpy="1.5707963267948966 1.832595714594046 1.5707963267948966" xyz="-0.01 -0.4 -0.077"/>
      <geometry>
        <mesh filename="package://fonbot_package/models/ultrasonic.dae" scale="0.3 0.3 0.3"/>
      </geometry>
    </collision>
    <!-- <xacro:inertial_box mass="0.05" x="0.2" y="0.2" z="0.2">
            <origin xyz="0 0 0" rpy="0 0 0" />
        </xacro:inertial_box> -->
  </link>
  <!-- Specify some standard inertial calculations https://en.wikipedia.org/wiki/List_of_moments_of_inertia -->
  <!-- These make use of xacro's mathematical functionality -->
  <joint name="ultrasonic_bottom_back_joint" type="fixed">
    <parent link="chassis"/>
    <child link="ultrasonic_bottom_back"/>
    <origin xyz="0 0.205 0.125"/>
  </joint>
  <link name="ultrasonic_bottom_back">
    <visual>
      <origin rpy="1.5707963267948966 0.28559933214452665 1.5707963267948966" xyz="-0.01 -0.29 -0.1"/>
      <geometry>
        <mesh filename="package://fonbot_package/models/ultrasonic.dae" scale="0.3 0.3 0.3"/>
      </geometry>
    </visual>
    <collision>
      <origin rpy="1.5707963267948966 1.832595714594046 1.5707963267948966" xyz="-0.01 -0.4 -0.077"/>
      <geometry>
        <mesh filename="package://fonbot_package/models/ultrasonic.dae" scale="0.3 0.3 0.3"/>
      </geometry>
    </collision>
    <!-- <xacro:inertial_box mass="0.05" x="0.2" y="0.2" z="0.2">
            <origin xyz="0 0 0" rpy="0 0 0" />
        </xacro:inertial_box> -->
  </link>
  <!-- Specify some standard inertial calculations https://en.wikipedia.org/wiki/List_of_moments_of_inertia -->
  <!-- These make use of xacro's mathematical functionality -->
  <joint name="camera_joint" type="fixed">
    <parent link="head"/>
    <child link="camera"/>
    <!-- <origin xyz="0 0.205 0.125" /> -->
  </joint>
  <link name="camera">
    <visual>
      <origin rpy="-1.5707963267948966 1.3463968515384828 1.5707963267948966" xyz="0 0.0762 0.111"/>
      <geometry>
        <mesh filename="package://fonbot_package/models/camera.dae" scale="0.017 0.017 0.017"/>
      </geometry>
    </visual>
    <collision>
      <origin rpy="-1.5707963267948966 1.3463968515384828 1.5707963267948966" xyz="0 0.0762 0.111"/>
      <geometry>
        <mesh filename="package://fonbot_package/models/camera.dae" scale="0.017 0.017 0.017"/>
      </geometry>
    </collision>
    <inertial>
      <origin rpy="-1.5707963267948966 1.3463968515384828 1.5707963267948966" xyz="0 0.0762 0.111"/>
      <mass value="0.05"/>
      <inertia ixx="3.3333333333333333e-06" ixy="0.0" ixz="0.0" iyy="3.3333333333333333e-06" iyz="0.0" izz="3.3333333333333333e-06"/>
    </inertial>
  </link>
  <!-- Specify some standard inertial calculations https://en.wikipedia.org/wiki/List_of_moments_of_inertia -->
  <!-- These make use of xacro's mathematical functionality -->
  <joint name="microphone_joint" type="fixed">
    <parent link="head"/>
    <child link="microphone"/>
  </joint>
  <link name="microphone">
    <visual>
      <origin rpy="3.141592653589793 -1.3463968515384828 1.5707963267948966" xyz="0 0.08 -0.113"/>
      <geometry>
        <mesh filename="package://fonbot_package/models/microphone.stl" scale="0.008 0.008 0.008"/>
      </geometry>
      <material name="black">
        <color rgba="0 0 0 1"/>
      </material>
    </visual>
    <collision>
      <origin rpy="3.141592653589793 -1.3463968515384828 1.5707963267948966" xyz="0 0.08 -0.113"/>
      <geometry>
        <mesh filename="package://fonbot_package/models/microphone.stl" scale="0.008 0.008 0.008"/>
      </geometry>
    </collision>
    <inertial>
      <origin rpy="3.141592653589793 -1.3463968515384828 1.5707963267948966" xyz="0 0.08 -0.113"/>
      <mass value="0.05"/>
      <inertia ixx="3.3333333333333333e-06" ixy="0.0" ixz="0.0" iyy="3.3333333333333333e-06" iyz="0.0" izz="3.3333333333333333e-06"/>
    </inertial>
  </link>
</robot>
